Workbook
Name order: 'Ecommerce_Raw_Data (2)'!$N$3
Name orders: 'Ecommerce_Raw_Data (2)'!$N$3

Sheet Ecommerce_Raw_Data (2)
A1: OrderID | B1: OrderDate | C1: Category | D1: Product | E1: State | F1: Quantity | G1: UnitPrice | H1: Discount% | I1: OrderStatus | J1: PaymentMode | K1: Channel | L1: OrderAmount | M1: month | N1: sales bucket
A2: OD20001 | B2: 45625 | C2: Home | D2: Wall Clock | E2: West Bengal | F2: 1 | G2: 718.62 | H2: 0 | I2: Delivered | J2: COD | K2: Website | L2: 718.62 | M2: =TEXT(B2,"mmm") -> Nov | N2: =IF(L2>20000,"high",IF(L2>10000,"medium","low")) -> low
A3: OD20002 | B3: 45322 | C3: Fashion | D3: T-Shirt | E3: West Bengal | F3: 5 | G3: 1121.85 | H3: 0.1 | I3: Pending | J3: Credit Card | K3: Website | L3: 5048.32 | M3: =TEXT(B3,"mmm") -> Jan | N3: =IF(L3>20000,"high",IF(L3>10000,"medium","low")) -> low | P3: discount change
A4: OD20003 | B4: 45506 | C4: Books | D4: Notebook | E4: Tamil Nadu | F4: 2 | G4: 4394.38 | H4: 0.1 | I4: Returned | J4: Debit Card | K4: Website | L4: 7909.88 | M4: =TEXT(B4,"mmm") -> Aug | N4: =IF(L4>20000,"high",IF(L4>10000,"medium","low")) -> low
A5: OD20004 | B5: 45608 | C5: Books | D5: Novel | E5: Delhi | F5: 2 | G5: 4046.85 | H5: 0.2 | I5: Delivered | J5: Credit Card | K5: Mobile App | L5: 6474.96 | M5: =TEXT(B5,"mmm") -> Nov | N5: =IF(L5>20000,"high",IF(L5>10000,"medium","low")) -> low | S5: 12344 | T5: text | U5: 234 | V5: =U5*1 -> 234
A6: OD20005 | B6: 45560 | C6: Electronics | D6: Phone Cover | E6: Tamil Nadu | F6: 4 | G6: 7019.83 | H6: 0.25 | I6: Delivered | J6: Debit Card | K6: Mobile App | L6: 21059.49 | M6: =TEXT(B6,"mmm") -> Sep | N6: =IF(L6>20000,"high",IF(L6>10000,"medium","low")) -> high | S6: 4562 | T6: no | U6: 321 | V6: =U6*1 -> 321
A7: OD20006 | B7: 45634 | C7: Beauty | D7: Hair Oil | E7: Delhi | F7: 1 | G7: 6151.88 | H7: 0.15 | I7: Delivered | J7: UPI | K7: Mobile App | L7: 5229.1 | M7: =TEXT(B7,"mmm") -> Dec | N7: =IF(L7>20000,"high",IF(L7>10000,"medium","low")) -> low | U7: 345 | V7: =U7*1 -> 345
A8: OD20007 | B8: 45651 | C8: Beauty | D8: Face Wash | E8: Delhi | F8: 3 | G8: 5229.96 | H8: 0.25 | I8: Delivered | J8: Debit Card | K8: Mobile App | L8: 11767.41 | M8: =TEXT(B8,"mmm") -> Dec | N8: =IF(L8>20000,"high",IF(L8>10000,"medium","low")) -> medium | U8: 2134 | V8: =U8*1 -> 2134
A9: OD20008 | B9: 45322 | C9: Books | D9: Novel | E9: Rajasthan | F9: 2 | G9: 6180.63 | H9: 0.05 | I9: Pending | J9: COD | K9: Mobile App | L9: 11743.2 | M9: =TEXT(B9,"mmm") -> Jan | N9: =IF(L9>20000,"high",IF(L9>10000,"medium","low")) -> medium | U9: 2 | V9: =U9*1 -> 2
A10: OD20009 | B10: 45512 | C10: Books | D10: Comic | E10: Karnataka | F10: 5 | G10: 2335.61 | H10: 0.2 | I10: Delivered | J10: Credit Card | K10: Mobile App | L10: 9342.44 | M10: =TEXT(B10,"mmm") -> Aug | N10: =IF(L10>20000,"high",IF(L10>10000,"medium","low")) -> low
A11: OD20010 | B11: 45593 | C11: Fashion | D11: T-Shirt | E11: Rajasthan | F11: 2 | G11: 2212.56 | H11: 0 | I11: Delivered | J11: Wallet | K11: Website | L11: 4425.12 | M11: =TEXT(B11,"mmm") -> Oct | N11: =IF(L11>20000,"high",IF(L11>10000,"medium","low")) -> low
A12: OD20011 | B12: 45495 | C12: Beauty | D12: Sunscreen | E12: West Bengal | F12: 4 | G12: 3243.84 | H12: 0.25 | I12: Pending | J12: UPI | K12: Mobile App | L12: 9731.52 | M12: =TEXT(B12,"mmm") -> Jul | N12: =IF(L12>20000,"high",IF(L12>10000,"medium","low")) -> low | U12: must multiply text no with 1
A13: OD20012 | B13: 45292 | C13: Books | D13: Novel | E13: Maharashtra | F13: 5 | G13: 1337.43 | H13: 0 | I13: Delivered | J13: Debit Card | K13: Mobile App | L13: 6687.15 | M13: =TEXT(B13,"mmm") -> Jan | N13: =IF(L13>20000,"high",IF(L13>10000,"medium","low")) -> low | U13: then drag theal ctrl +alt + v
A14: OD20013 | B14: 45354 | C14: Books | D14: Comic | E14: Rajasthan | F14: 1 | G14: 6814.15 | H14: 0.25 | I14: Cancelled | J14: Debit Card | K14: Mobile App | L14: 5110.61 | M14: =TEXT(B14,"mmm") -> Mar | N14: =IF(L14>20000,"high",IF(L14>10000,"medium","low")) -> low
A15: OD20014 | B15: 45397 | C15: Fashion | D15: Handbag | E15: Delhi | F15: 5 | G15: 2989.76 | H15: 0 | I15: Returned | J15: Wallet | K15: Mobile App | L15: 14948.8 | M15: =TEXT(B15,"mmm") -> Apr | N15: =IF(L15>20000,"high",IF(L15>10000,"medium","low")) -> medium
A16: OD20015 | B16: 45564 | C16: Fashion | D16: Jeans | E16: Up | F16: 5 | G16: 6265.58 | H16: 0.15 | I16: Pending | J16: Credit Card | K16: Mobile App | L16: 26628.72 | M16: =TEXT(B16,"mmm") -> Sep | N16: =IF(L16>20000,"high",IF(L16>10000,"medium","low")) -> high
A17: OD20016 | B17: 45474 | C17: Fashion | D17: Kurti | E17: Rajasthan | F17: 6 | G17: 377.49 | H17: 0 | I17: Delivered | J17: Debit Card | K17: Mobile App | L17: 2264.94 | M17: =TEXT(B17,"mmm") -> Jul | N17: =IF(L17>20000,"high",IF(L17>10000,"medium","low")) -> low
A18: OD20017 | B18: 45408 | C18: Electronics | D18: Power Bank | E18: Maharashtra | F18: 4 | G18: 1694.14 | H18: 0.1 | I18: Cancelled | J18: Debit Card | K18: Website | L18: 6098.9 | M18: =TEXT(B18,"mmm") -> Apr | N18: =IF(L18>20000,"high",IF(L18>10000,"medium","low")) -> low
A19: OD20018 | B19: 45536 | C19: Electronics | D19: Bluetooth Speaker | E19: Up | F19: 2 | G19: 3556.31 | H19: 0.15 | I19: Delivered | J19: UPI | K19: Mobile App | L19: 6045.73 | M19: =TEXT(B19,"mmm") -> Sep | N19: =IF(L19>20000,"high",IF(L19>10000,"medium","low")) -> low
A20: OD20019 | B20: 45369 | C20: Fashion | D20: Kurti | E20: Delhi | F20: 5 | G20: 7253.09 | H20: 0.05 | I20: Returned | J20: Wallet | K20: Mobile App | L20: 34452.18 | M20: =TEXT(B20,"mmm") -> Mar | N20: =IF(L20>20000,"high",IF(L20>10000,"medium","low")) -> high
A21: OD20020 | B21: 45561 | C21: Electronics | D21: Earbuds | E21: Maharashtra | F21: 6 | G21: 7478.95 | H21: 0.2 | I21: Delivered | J21: Credit Card | K21: Mobile App | L21: 35898.96 | M21: =TEXT(B21,"mmm") -> Sep | N21: =IF(L21>20000,"high",IF(L21>10000,"medium","low")) -> high
A22: OD20021 | B22: 45359 | C22: Home | D22: Curtain | E22: West Bengal | F22: 1 | G22: 7293.63 | H22: 0.15 | I22: Cancelled | J22: Wallet | K22: Mobile App | L22: 6199.59 | M22: =TEXT(B22,"mmm") -> Mar | N22: =IF(L22>20000,"high",IF(L22>10000,"medium","low")) -> low
A23: OD20022 | B23: 45517 | C23: Books | D23: Notebook | E23: Delhi | F23: 2 | G23: 4927.15 | H23: 0.05 | I23: Delivered | J23: Wallet | K23: Mobile App | L23: 9361.58 | M23: =TEXT(B23,"mmm") -> Aug | N23: =IF(L23>20000,"high",IF(L23>10000,"medium","low")) -> low
A24: OD20023 | B24: 45419 | C24: Electronics | D24: Phone Cover | E24: Delhi | F24: 2 | G24: 2323.8 | H24: 0 | I24: Returned | J24: Debit Card | K24: Mobile App | L24: 4647.6 | M24: =TEXT(B24,"mmm") -> May | N24: =IF(L24>20000,"high",IF(L24>10000,"medium","low")) -> low
A25: OD20024 | B25: 45551 | C25: Home | D25: Table Lamp | E25: Rajasthan | F25: 2 | G25: 5638.86 | H25: 0.1 | I25: Returned | J25: COD | K25: Mobile App | L25: 10149.95 | M25: =TEXT(B25,"mmm") -> Sep | N25: =IF(L25>20000,"high",IF(L25>10000,"medium","low")) -> medium
... A29: OD20028 | B29: 45335 | C29: Electronics | D29: Power Bank | E29: Maharashtra | F29: 3 | G29: 2284.58 | H29: 0.05 | I29: Delivered | J29: Debit Card | K29: Mobile App | L29: 6511.05 | M29: =TEXT(B29,"mmm") -> Feb | N29: =IF(L29>20000,"high",IF(L29>10000,"medium","low")) -> low
A30: OD20029 | B30: 45650 | C30: Fashion | D30: Handbag | E30: Rajasthan | F30: 3 | G30: 852.28 | H30: 0 | I30: Pending | J30: UPI | K30: Mobile App | L30: =(F30*G30)-(F30*G30)*H30 -> 2556.84 | M30: =TEXT(B30,"mmm") -> Dec | N30: =IF(L30>20000,"high",IF(L30>10000,"medium","low")) -> low
A31: OD20030 | B31: 45326 | C31: Electronics | D31: Phone Cover | E31: Up | F31: 3 | G31: 6922.78 | H31: 0.25 | I31: Delivered | J31: Credit Card | K31: Website | L31: 15576.26 | M31: =TEXT(B31,"mmm") -> Feb | N31: =IF(L31>20000,"high",IF(L31>10000,"medium","low")) -> medium
A32: OD20031 | B32: 45374 | C32: Books | D32: Notebook | E32: Maharashtra | F32: 3 | G32: 545.48 | H32: 0.1 | I32: Delivered | J32: Credit Card | K32: Mobile App | L32: 1472.8 | M32: =TEXT(B32,"mmm") -> Mar | N32: =IF(L32>20000,"high",IF(L32>10000,"medium","low")) -> low
A33: OD20032 | B33: 45310 | C33: Home | D33: Bedsheet | E33: Tamil Nadu | F33: 1 | G33: 294.71 | H33: 0.1 | I33: Returned | J33: COD | K33: Mobile App | L33: 265.24 | M33: =TEXT(B33,"mmm") -> Jan | N33: =IF(L33>20000,"high",IF(L33>10000,"medium","low")) -> low
A34: OD20033 | B34: 45644 | C34: Books | D34: Guide Book | E34: Tamil Nadu | F34: 2 | G34: 7862.16 | H34: 0.15 | I34: Delivered | J34: Debit Card | K34: Website | L34: 13365.67 | M34: =TEXT(B34,"mmm") -> Dec | N34: =IF(L34>20000,"high",IF(L34>10000,"medium","low")) -> medium
A35: OD20034 | B35: 45612 | C35: Fashion | D35: T-Shirt | E35: Maharashtra | F35: 6 | G35: 7056.86 | H35: 0.2 | I35: Delivered | J35: Debit Card | K35: Mobile App | L35: 33872.93 | M35: =TEXT(B35,"mmm") -> Nov | N35: =IF(L35>20000,"high",IF(L35>10000,"medium","low")) -> high
A36: OD20035 | B36: 45386 | C36: Home | D36: Bedsheet | E36: Rajasthan | F36: 2 | G36: 2261.94 | H36: 0 | I36: Delivered | J36: UPI | K36: Mobile App | L36: 4523.88 | M36: =TEXT(B36,"mmm") -> Apr | N36: =IF(L36>20000,"high",IF(L36>10000,"medium","low")) -> low
A37: OD20036 | B37: 45292 | C37: Fashion | D37: Jeans | E37: Karnataka | F37: 3 | G37: 3145.77 | H37: 0.25 | I37: Delivered | J37: Debit Card | K37: Website | L37: =(F37*G37)-(F37*G37)*H37 -> 7077.9825 | M37: =TEXT(B37,"mmm") -> Jan | N37: =IF(L37>20000,"high",IF(L37>10000,"medium","low")) -> low
A38: OD20037 | B38: 45493 | C38: Fashion | D38: Sneakers | E38: Delhi | F38: 1 | G38: 2502.22 | H38: 0.1 | I38: Delivered | J38: Wallet | K38: Mobile App | L38: 2252 | M38: =TEXT(B38,"mmm") -> Jul | N38: =IF(L38>20000,"high",IF(L38>10000,"medium","low")) -> low
A39: OD20038 | B39: 45437 | C39: Home | D39: Table Lamp | E39: Karnataka | F39: 6 | G39: 5006.85 | H39: 0.05 | I39: Delivered | J39: Wallet | K39: Mobile App | L39: 28539.05 | M39: =TEXT(B39,"mmm") -> May | N39: =IF(L39>20000,"high",IF(L39>10000,"medium","low")) -> high
A40: OD20039 | B40: 45643 | C40: Books | D40: Diary | E40: Delhi | F40: 5 | G40: 6414.04 | H40: 0.1 | I40: Delivered | J40: COD | K40: Website | L40: 28863.18 | M40: =TEXT(B40,"mmm") -> Dec | N40: =IF(L40>20000,"high",IF(L40>10000,"medium","low")) -> high
A41: OD20040 | B41: 45542 | C41: Electronics | D41: Phone Cover | E41: Up | F41: 3 | G41: 176.02 | H41: 0 | I41: Pending | J41: COD | K41: Mobile App | L41: 528.06 | M41: =TEXT(B41,"mmm") -> Sep | N41: =IF(L41>20000,"high",IF(L41>10000,"medium","low")) -> low
A42: OD20041 | B42: 45397 | C42: Electronics | D42: Smartwatch | E42: Up | F42: 2 | G42: 5957.65 | H42: 0.25 | I42: Cancelled | J42: UPI | K42: Mobile App | L42: 8936.47 | M42: =TEXT(B42,"mmm") -> Apr | N42: =IF(L42>20000,"high",IF(L42>10000,"medium","low")) -> low
A43: OD20042 | B43: 45461 | C43: Electronics | D43: Phone Cover | E43: Karnataka | F43: 3 | G43: 5264.54 | H43: 0.1 | I43: Returned | J43: UPI | K43: Mobile App | L43: 14214.26 | M43: =TEXT(B43,"mmm") -> Jun | N43: =IF(L43>20000,"high",IF(L43>10000,"medium","low")) -> medium
...

Sheet analysis
A1: Extracted Text from the Image
A3: Business Question | B3: Formula
A4: Total Orders kitne? | B4: =COUNTA(OrderID)
A5: Total Revenue? | B5: =SUM(OrderAmount)
A6: Average Order Value? | B6: =AVERAGE(OrderAmount)
A7: Delivered orders? | B7: =COUNTIF(Status,"Delivered")
A8: Cancelled orders? | B8: =COUNTIF(Status,"Cancelled")
A9: UPI se kitna revenue? | B9: =SUMIF(Pay,"UPI",Amount)
A10: App vs Website orders? | B10: =COUNTIF(Channel,"Mobile App")
A11: Electronics ka revenue? | B11: =SUMIF(Cat,"Electronics",Amount)
A13: Business Questions in Simple Form
A15: 1. Total Orders? | B15: =COUNTA(Table1[OrderID]) -> 1100
A17: 2. Total Revenue? | B17: =SUM(Table1[OrderAmount]) -> 13437722
A19: 3. Average Order Value? | B19: =AVERAGE('Ecommerce_Raw_Data (2)'!L1071:L1101) -> 10886.493
A21: 4. Delivered Orders? | B21: =COUNTIF(Table1[OrderStatus],'Ecommerce_Raw_Data (2)'!I1072) -> 554
A23: 5. Cancelled Orders? | B23: =COUNTIF(Table1[OrderStatus],'Ecommerce_Raw_Data (2)'!I1077) -> 177
A25: 6. Revenue from UPI Payments? | B25: =SUMIF(Table1[PaymentMode],"upi",Table1[OrderAmount]) -> 2734927.4
A27: 7. Mobile App vs Website Orders? | B27: =COUNTIF(Table1[Channel],'Ecommerce_Raw_Data (2)'!K1071) -> 841
A29: 8. Revenue from Electronics Category? | B29: =SUMIF(Table1[Category],'Ecommerce_Raw_Data (2)'!C1097,Table1[OrderAmount]) -> 2547506.6

Sheet pivot
A1: Category Revenue | E1: State Revenue | H1: Month Trend | K1: Status Count
A2: Row Labels | B2: Sum of OrderAmount | E2: Row Labels | F2: Sum of OrderAmount | H2: Row Labels | I2: Sum of OrderAmount | K2: Row Labels | L2: Count of OrderID | N2: Count of OrderID
A3: Beauty | B3: 2580125.7 | E3: Delhi | F3: 1647601.5 | H3: Jan | I3: 890424.49 | K3: Cancelled | L3: 177 | N3: 1100
A4: Books | B4: 2899898.1 | E4: Gujarat | F4: 1400504.8 | H4: Feb | I4: 1188321.7 | K4: Delivered | L4: 554
A5: Electronics | B5: 2547506.6 | E5: Karnataka | F5: 1484774.8 | H5: Mar | I5: 1310963.7 | K5: Pending | L5: 189 | N5: Average of OrderAmount
A6: Fashion | B6: 3200616.5 | E6: Maharashtra | F6: 2049161.2 | H6: Apr | I6: 1017549.3 | K6: Returned | L6: 180 | N6: 12216.111
A7: Home | B7: 2209574.6 | E7: Rajasthan | F7: 1654906.4 | H7: May | I7: 964522.14 | K7: Grand Total | L7: 1100
A8: Grand Total | B8: 13437722 | E8: Tamil Nadu | F8: 1706124.8 | H8: Jun | I8: 1256588.8 | N8: Sum of OrderAmount
E9: Up | F9: 1697372.7 | H9: Jul | I9: 1470854.8 | N9: 13437722
E10: West Bengal | F10: 1797275.4 | H10: Aug | I10: 1002404.1
E11: Grand Total | F11: 13437722 | H11: Sep | I11: 1141100.5 | N11: Row Labels | O11: Count of OrderAmount
H12: Oct | I12: 1274850.4 | N12: Delivered | O12: 554
H13: Nov | I13: 932916.36 | N13: Grand Total | O13: 554
H14: Dec | I14: 987225.39
H15: Grand Total | I15: 13437722
E18: Channel Split | H18: Payment Mode
E19: Row Labels | F19: Sum of OrderAmount | H19: Row Labels | I19: Sum of OrderAmount
E20: Mobile App | F20: 10090942 | H20: COD | I20: 2688398.2
E21: Website | F21: 3346779.4 | H21: Credit Card | I21: 2356422.1
E22: Grand Total | F22: 13437722 | H22: Debit Card | I22: 2669094
H23: UPI | I23: 2734927.4
H24: Wallet | I24: 2988880

Sheet dashboard
